Workbook

Sheet Load Torque
B2: Load Torque | C2: Torque requried to overcome steady/continuous load
A6: 1.1 | B6: Load Torque @ Ballscrew Shaft
A7: 1.2 | B7: Load Torque @ Parallel kit input
A8: 1.3 | B8: Load Torque @ Gearbox input shaft
B13: Parameter | C13: Symbol | D13: Unit | E13: value | F13: Remarks
B16: Load Torque @ ballscrew shaft | C16: Tl | D16: Nm | E16: =E74+E82+E88 -> 0.065019701 | F16: Load Torque @ ballscrew shaft = Axial Force torque +/- ballscrew preload torque +/- ballscrew bearing drag torque
A19: 1 | B19: Axial Force | C19: F | D19: N | E19: =E23+E28+E46+E58 -> 15.443779
B20: Axial Force = +/- external force +/- gravitational force +/- frictional force +/- counterbalance force
A22: 1.1 | B22: External Force | D22: N | E22: 5
E23: =IF(E24="aiding movement",-E22,+E22) -> 5 | F23: use sign based on sign matrix
B24: direction of External force | E24: opposing movement
A27: 1.2 | B27: Gravitational Force | C27: Fg | D27: N | E27: =E32*E41*SIN(E43) -> 41.287343
E28: =IF(E30="gravity aided",-E27,+E27) -> 41.287343 | F28: use sign based on sign matrix
B29: Gravitational force = m*g*sinθ
B30: movement direction | E30: against gravity
A32: 1.2.1 | B32: Total moving mass | C32: m | D32: Kg | E32: =E35+E36+E37+(E38*E39) -> 5.952
B34: Total moving mass = payload mass + carriage mass + ballscrew nut & housing mass + Linear guide carriage blocks mass
B35: Payload mass | C35: mp | D35: Kg | E35: 5
B36: Carriage mass | C36: mc | D36: Kg | E36: 0.5 | J36: Ballscrew | K36: THK SDA1005VZ-4TTG0+171LC5Y
B37: Ballscrew nut mass | C37: mn | D37: Kg | E37: 0.052 | J37: LM rail | K37: SSR15
B38: Linear guide carriage block mass | C38: ml | D38: kg | E38: 0.2 | F38: per block | J38: LM block | K38: SSR15XW
B39: number of carriage blocks | D39: - | E39: 2
A41: 1.2.2 | B41: gravitational acceleration | C41: g | D41: m/s2 | E41: 9.81
A42: 1.2.3 | B42: Inclination angle | C42: θ | D42: deg | E42: 45
D43: radians | E43: =RADIANS(E42) -> 0.78539816
A44: 1.2.4 | B44: Friction coefficient of linear guide | C44: μ | D44: - | E44: 0.005
A46: 1.3 | B46: Friction force | C46: Ff | D46: N | E46: =E48+E50+E54 -> 18.206437 | F46: Friction force = Fpl + Ffp + Ffcb
A48: 1.3.1 | B48: Payload friction force | C48: Fpl | D48: N | E48: =E32*E41*E44*COS(E43) -> 0.20643671 | F48: m*g*μ*cosθ
A50: 1.3.2 | B50: Guide friction force (payload side) | C50: Ffp | D50: N | E50: =E51*E52 -> 6
B51: LM guide frcition force (payload) | C51: Fgf | D51: N | E51: 3 | F51: per block
B52: number of carriage blocks (payload) | D52: - | E52: =E39 -> 2
A54: 1.3.3 | B54: Guide friction force(counterbalance side) | C54: Ffcb | D54: N | E54: =IF(E63="yes",E55*E56,0) -> 12 | F54: 0 if counterbalance is not present
B55: Linear bush frcition force (counterbalance) | C55: Fgfcb | D55: N | E55: 3 | F55: per bushing | J55: round shaft | K55: 15mm
B56: number of linear bushings (counterbalance) | D56: - | E56: 4 | J56: linear bushing | K56: THK LMK15UU
A58: 1.4 | B58: Counter balance force | C58: Fcb | D58: N | E58: =IF(E65="Assisting movement",-E59,+E59) -> -49.05
E59: =IF(E63="yes",E60,0) -> 49.05 | F59: counterbalance present
E60: =E64*E68*(SIN(E70)+(E71*COS(E70))) -> 49.05 | F60: calculated value
B61: Counter balance force = m*g*(sinθ + μcosθ)
A63: 1.4.1 | B63: Counter balance exists | E63: yes
A64: 1.4.2 | B64: mass of the counterbalance | C64: mcb | D64: Kg | E64: 5
...

Sheet Axial Force sign matrix
A2: Motor-effort sign matrix using updated Load Torque sheet names
A3: + = increases motor effort for that phase; - = reduces motor effort; NA = not applicable / zero for that axis. Use ABS() separately for motor capacity checks.
A5: Counter balance exists | B5: Axis | C5: movement direction | D5: Motion phase | E5: External Force (opposing movement) | F5: External Force (aiding movement) | G5: Gravitational Force | H5: Payload friction force | I5: Guide friction force (payload side) | J5: Guide friction force(counterbalance side) | K5: Friction force | L5: Counter balance force | M5: Ballscrew Preload Torque | N5: Fixed side support block drag torque | O5: Support side support block drag torque | P5: Ball screw bearing drag torque | Q5: Comment
A6: no | B6: Horizontal | C6: Either direction | D6: Acceleration | E6: + | F6: - | G6: NA | H6: + | I6: + | J6: NA | K6: + | L6: NA | M6: + | N6: + | O6: + | P6: + | Q6: Updated sheet now uses Gravitational force = m*g*sinθ, so horizontal Gravitational Force is zero/NA. Payload friction force and guide friction force remain active.
A7: no | B7: Horizontal | C7: Either direction | D7: Top speed | E7: + | F7: - | G7: NA | H7: + | I7: + | J7: NA | K7: + | L7: NA | M7: + | N7: + | O7: + | P7: + | Q7: Updated sheet now uses Gravitational force = m*g*sinθ, so horizontal Gravitational Force is zero/NA. Payload friction force and guide friction force remain active.
A8: no | B8: Horizontal | C8: Either direction | D8: Deceleration | E8: - | F8: + | G8: NA | H8: - | I8: - | J8: NA | K8: - | L8: NA | M8: - | N8: - | O8: - | P8: - | Q8: Updated sheet now uses Gravitational force = m*g*sinθ, so horizontal Gravitational Force is zero/NA. Payload friction force and guide friction force remain active.
A9: no | B9: Vertical / inclined | C9: against gravity | D9: Acceleration | E9: + | F9: - | G9: + | H9: + | I9: + | J9: NA | K9: + | L9: NA | M9: + | N9: + | O9: + | P9: + | Q9: Payload moving against gravity: Gravitational Force increases effort in accel/top and helps stopping in decel.
A10: no | B10: Vertical / inclined | C10: against gravity | D10: Top speed | E10: + | F10: - | G10: + | H10: + | I10: + | J10: NA | K10: + | L10: NA | M10: + | N10: + | O10: + | P10: + | Q10: Payload moving against gravity: Gravitational Force increases effort in accel/top and helps stopping in decel.
A11: no | B11: Vertical / inclined | C11: against gravity | D11: Deceleration | E11: - | F11: + | G11: - | H11: - | I11: - | J11: NA | K11: - | L11: NA | M11: - | N11: - | O11: - | P11: - | Q11: Payload moving against gravity: Gravitational Force increases effort in accel/top and helps stopping in decel.
A12: no | B12: Vertical / inclined | C12: gravity aided | D12: Acceleration | E12: + | F12: - | G12: - | H12: + | I12: + | J12: NA | K12: + | L12: NA | M12: + | N12: + | O12: + | P12: + | Q12: Payload moving with gravity: Gravitational Force reduces effort in accel/top and increases braking effort in decel.
A13: no | B13: Vertical / inclined | C13: gravity aided | D13: Top speed | E13: + | F13: - | G13: - | H13: + | I13: + | J13: NA | K13: + | L13: NA | M13: + | N13: + | O13: + | P13: + | Q13: Payload moving with gravity: Gravitational Force reduces effort in accel/top and increases braking effort in decel.
A14: no | B14: Vertical / inclined | C14: gravity aided | D14: Deceleration | E14: - | F14: + | G14: + | H14: - | I14: - | J14: NA | K14: - | L14: NA | M14: - | N14: - | O14: - | P14: - | Q14: Payload moving with gravity: Gravitational Force reduces effort in accel/top and increases braking effort in decel.
A15: yes | B15: Horizontal | C15: Either direction | D15: Acceleration | E15: + | F15: - | G15: NA | H15: + | I15: + | J15: Treat as External Force | K15: + | L15: Treat as External Force | M15: + | N15: + | O15: + | P15: + | Q15: For a horizontal axis, a spring/cylinder/counter-force should be entered as External Force, not as vertical Counter balance force.
A16: yes | B16: Horizontal | C16: Either direction | D16: Top speed | E16: + | F16: - | G16: NA | H16: + | I16: + | J16: Treat as External Force | K16: + | L16: Treat as External Force | M16: + | N16: + | O16: + | P16: + | Q16: For a horizontal axis, a spring/cylinder/counter-force should be entered as External Force, not as vertical Counter balance force.
... A23: yes | B23: Vertical / inclined | C23: gravity aided | D23: Deceleration | E23: - | F23: + | G23: + | H23: - | I23: - | J23: - | K23: - | L23: - | M23: - | N23: - | O23: - | P23: - | Q23: Downward/gravity-aided decel: gravity increases braking effort, while counterbalance and drag help stopping.
A26: Case | B26: Motion phase | C26: Motor-effort load torque expression using updated sheet names
A27: Horizontal, no counterbalance | B27: Acceleration | C27: +External Force(opposing) '-External Force(aiding) '+Payload friction force '+Guide friction force (payload side) '+Ballscrew Preload Torque '+Ball screw bearing drag torque
A28: Horizontal, no counterbalance | B28: Top speed | C28: +External Force(opposing) '-External Force(aiding) '+Payload friction force '+Guide friction force (payload side) '+Ballscrew Preload Torque '+Ball screw bearing drag torque
A29: Horizontal, no counterbalance | B29: Deceleration | C29: -External Force(opposing) '+External Force(aiding) '-Payload friction force '-Guide friction force (payload side) '-Ballscrew Preload Torque '-Ball screw bearing drag torque
A30: Vertical/inclined, no counterbalance, movement direction = against gravity | B30: Acceleration | C30: +External Force(opposing) '-External Force(aiding) '+Gravitational Force '+Payload friction force '+Guide friction force (payload side) '+Ballscrew Preload Torque '+Ball screw bearing drag torque
A31: Vertical/inclined, no counterbalance, movement direction = against gravity | B31: Top speed | C31: +External Force(opposing) '-External Force(aiding) '+Gravitational Force '+Payload friction force '+Guide friction force (payload side) '+Ballscrew Preload Torque '+Ball screw bearing drag torque
A32: Vertical/inclined, no counterbalance, movement direction = against gravity | B32: Deceleration | C32: -External Force(opposing) '+External Force(aiding) '-Gravitational Force '-Payload friction force '-Guide friction force (payload side) '-Ballscrew Preload Torque '-Ball screw bearing drag torque
A33: Vertical/inclined, no counterbalance, movement direction = gravity aided | B33: Acceleration | C33: +External Force(opposing) '-External Force(aiding) '-Gravitational Force '+Payload friction force '+Guide friction force (payload side) '+Ballscrew Preload Torque '+Ball screw bearing drag torque
A34: Vertical/inclined, no counterbalance, movement direction = gravity aided | B34: Top speed | C34: +External Force(opposing) '-External Force(aiding) '-Gravitational Force '+Payload friction force '+Guide friction force (payload side) '+Ballscrew Preload Torque '+Ball screw bearing drag torque
A35: Vertical/inclined, no counterbalance, movement direction = gravity aided | B35: Deceleration | C35: -External Force(opposing) '+External Force(aiding) '+Gravitational Force '-Payload friction force '-Guide friction force (payload side) '-Ballscrew Preload Torque '-Ball screw bearing drag torque
A36: Vertical/inclined, counterbalance exists = yes, movement direction = against gravity | B36: Acceleration | C36: +External Force(opposing) '-External Force(aiding) '+Gravitational Force '+Payload friction force '+Guide friction force (payload side) '+Guide friction force(counterbalance side) '-Counter balance force '+Ballscrew Preload Torque '+Ball screw bearing drag torque
A37: Vertical/inclined, counterbalance exists = yes, movement direction = against gravity | B37: Top speed | C37: +External Force(opposing) '-External Force(aiding) '+Gravitational Force '+Payload friction force '+Guide friction force (payload side) '+Guide friction force(counterbalance side) '-Counter balance force '+Ballscrew Preload Torque '+Ball screw bearing drag torque
... A41: Vertical/inclined, counterbalance exists = yes, movement direction = gravity aided | B41: Deceleration | C41: -External Force(opposing) '+External Force(aiding) '+Gravitational Force '-Payload friction force '-Guide friction force (payload side) '-Guide friction force(counterbalance side) '-Counter balance force '-Ballscrew Preload Torque '-Ball screw bearing drag torque

Sheet Speed calc
B1: Parameter | C1: Symbol | D1: Unit | E1: value | F1: Remarks
B2: RPM @ ballscrew shaft | D2: rpm | E2: =E4/E14 -> 257.14286 | F2: required rpm @ ballscrew shaft = calculated Topspeed/ballscrew pitch
A4: 1 | B4: Topspeed required | D4: m/min | E4: =(E5/1000)*60 -> 1.2857143
D5: mm/sec | E5: =E6*E14*1000 -> 21.428571
D6: rps | E6: =E15/(E9-(0.5*(E10+E11))) -> 4.2857143 | F6: max rev/sec = R/(t-(0.5*(ta+td)))
B7: Displacement | C7: S | D7: mm | E7: 15
D8: m | E8: =E7/1000 -> 0.015
B9: Time available for displacement | C9: t | D9: sec | E9: 0.9 | F9: Time for movement = ta+ tc+td
B10: time for acceleration | C10: ta | D10: sec | E10: 0.2
B11: time for decceleration | C11: td | D11: sec | E11: 0.2
B12: time for constant speed | C12: tc | D12: sec | E12: =E9-E10-E11 -> 0.5
B14: ballscrew lead | C14: Pb | D14: m | E14: ='Load Torque'!E86 -> 0.005
B15: req. rotations to reach displacement | C15: R | D15: rev | E15: =E8/E14 -> 3

Sheet Acceleration Torque
B1: Parameter | C1: Symbol | D1: Unit | E1: value | F1: Remarks
B2: Acceleration torque @ ballscrew shaft | F2: Acceleration Torque = Load inertia *(rotational speed/9.55*acceleration time)
B4: Total Acceleration Torque | C4: Ta | D4: Nm | E4: =E6*(E19/(9.55*E21)) -> 0.00068531326
A6: 1 | B6: Load inertia | C6: JL | D6: kg-m2 | E6: =E8+E13 -> 5.0903546e-06 | F6: Load inertia = inertia due to linear mass + inertia due to rotational mass
A8: 1.1 | B8: Inertia due to linear mass | C8: Jlm | D8: kg-m2 | E8: =E10*((E11/(2*PI()))^2) -> 3.769148e-06 | F8: Inertia due to linear mass = Total linear mass*(square(ballscrew lead/(2*pi))
A10: 1.1.1 | B10: Total linear mass | D10: Kg | E10: ='Load Torque'!E32 -> 5.952 | F10: Total moving mass = payload mass + carriage mass + ballscrew nut & housing mass + Linear guide carriage blocks mass
A11: 1.1.2 | B11: Ball screw lead | C11: Pb | D11: m | E11: ='Load Torque'!E78 -> 0.005
A13: 1.2 | B13: Inertia due to rotational mass | C13: Jrm | D13: kg-m2 | E13: =(PI()/32)*E17*E14*(E15^4) -> 1.3212066e-06 | F13: Rotational mass inertia = (pi/32)*density*Lb*(Db^4)
B14: Ball screw length | C14: Lb | D14: m | E14: =171/1000 -> 0.171
B15: Ballscrew diameter | C15: Db | D15: m | E15: =10/1000 -> 0.01
B16: Ballscrew material | E16: Mildsteel | G16: MS | H16: 7870
B17: Material density | D17: kg/m3 | E17: =IF(E16="Mildsteel",H16,IF(E16="Stainless steel",H17,IF(E16="Aluminium",H18,0))) -> 7870 | G17: SS | H17: 7930
G18: Al | H18: 2700
A19: 2 | B19: max rotational speed | D19: rpm | E19: ='Speed calc'!E2 -> 257.14286
A21: 3 | B21: acceleration time | D21: sec | E21: ='Speed calc'!E10 -> 0.2
B24: Decceleration torque @ ballscrew shaft | F24: Decceleration Torque = Load inertia *(rotational speed/9.55*decceleration time)
B26: Total Decceleration Torque | C26: Ta | D26: Nm | E26: =E28*(E41/(9.55*E43)) -> 0.00068531326
A28: 1 | B28: Load inertia | C28: JL | D28: kg-m2 | E28: =E30+E35 -> 5.0903546e-06 | F28: Load inertia = inertia due to linear mass + inertia due to rotational mass
A30: 1.1 | B30: Inertia due to linear mass | C30: Jlm | D30: kg-m2 | E30: =E32*((E33/(2*PI()))^2) -> 3.769148e-06 | F30: Inertia due to linear mass = Total linear mass*(square(ballscrew lead/(2*pi))
A32: 1.1.1 | B32: Total linear mass | D32: Kg | E32: ='Load Torque'!E32 -> 5.952 | F32: Total moving mass = payload mass + carriage mass + ballscrew nut & housing mass + Linear guide carriage blocks mass
A33: 1.1.2 | B33: Ball screw lead | C33: Pb | D33: m | E33: ='Load Torque'!E78 -> 0.005
A35: 1.2 | B35: Inertia due to rotational mass | C35: Jrm | D35: kg-m2 | E35: =(PI()/32)*E39*E36*(E37^4) -> 1.3212066e-06 | F35: Rotational mass inertia = (pi/32)*density*Lb*(Db^4)
B36: Ball screw length | C36: Lb | D36: m | E36: =E14 -> 0.171
B37: Ballscrew diameter | C37: Db | D37: m | E37: =E15 -> 0.01
B38: Ballscrew material | E38: =E16 -> Mildsteel | G38: MS | H38: 7870
B39: Material density | D39: kg/m3 | E39: =IF(E38="Mildsteel",H38,IF(E38="Stainless steel",H39,IF(E38="Aluminium",H40,0))) -> 7870 | G39: SS | H39: 7930
G40: Al | H40: 2700
A41: 2 | B41: max rotational speed | D41: rpm | E41: ='Speed calc'!E2 -> 257.14286
A43: 3 | B43: acceleration time | D43: sec | E43: ='Speed calc'!E11 -> 0.2

Sheet Total Torque Calculation
B1: Parameter | C1: Symbol | D1: Unit | E1: value | F1: Remarks
B2: Total Torque required @ ballscrew shaft for 0deg inclination and no counter balance
A4: 1 | B4: Torque during acceleration | D4: Nm | E4: 0.06571 | F4: {=Load Torque+acceleration Torque} -> #NAME?
A5: 1.1 | B5: Load Torque | C5: Tl | D5: Nm | E5: 0.07
A6: 1.2 | B6: Acceleration torque | C6: Ta | D6: Nm | E6: 0.00069
A9: 2 | B9: Torque during Topspeed | D9: Nm | E9: 0.06502 | F9: {=Load Torque} -> #NAME?
A12: 3 | B12: Torque during Decceleration | D12: Nm | E12: 0.06433 | F12: {=absoute(Decceleration Torque-Load Torque)} -> #NAME?
A13: 3.1 | B13: Decceleration Torque | C13: Td | D13: Nm | E13: 0.00069
A15: 4 | B15: Torque during Idle time | C15: Ti | D15: Nm | F15: {=Holding Torque} -> #NAME?
B18: Total Torque required @ ballscrew shaft for >0deg inclination and no counter balance
A20: 1 | B20: upward movement
A21: 1.1 | B21: Torque during acceleration | F21: {=Load Torque+acceleration Torque} -> #NAME?
A22: 1.2 | B22: Torque during Topspeed | F22: {=Load Torque} -> #NAME?
A23: 1.3 | B23: Torque during Decceleration | F23: {=absolute(Decceleration Torque-Load Torque)} -> #NAME?
A24: 1.4 | B24: Torque during Idle time
