Workbook

Sheet Image

Sheet calc
A1: Vertical Ball screw calculation - OP90
A3: Data Inputs
A4: Application requirement | B4: No of shifts per day | C4: 3 | D4: shifts | E4: Fixed accross project
B5: Working hours per shift | C5: 7 | D5: Hrs | E5: Fixed accross project
B6: Working hours per day | C6: =C4*C5 -> 21 | D6: hrs | E6: Fixed accross project
B7: Working days per Week | C7: 6 | D7: days | E7: Fixed accross project
B8: Total cycle time of machine | C8: 7 | D8: sec
B9: Total operating time per cycle | C9: 2.6 | D9: sec | E9: Sum of all operating time
B10: Expected service life of Machine | C10: 10 | D10: Yrs | E10: Fixed accross project
B11: Movement Stroke required | C11: 15 | D11: mm | E11: For first stroke and continuous for others
B12: Cycle time available for single movement | C12: 1 | D12: sec | E12: Break this into multiple movements
B13: External Force on the moving mass | C13: 250 | D13: N | E13: Break this into multiple movements
B14: Moving mass | C14: 1 | D14: kg | E14: Break this into multiple movements
B15: Tilt angle of the setup | C15: 45 | D15: deg | E15: To be later
B16: Acceleration time % | C16: 0.25 | D16: sec | E16: 50% of one single operating time
B17: Safety factor % | C17: 0.2 | E17: Fixed accross project
B18: Movement accuracy required (+/-) | C18: 10 | D18: micron | E18: Fixed accross project
A20: Ball screw Details | B20: Selected Ball screw model | C20: Festo - ESBF-BS-40-100-5P / 8022585
B21: Ball screw Friction Torque @ application speed + Ball screw no load torque | C21: 0.05 | D21: Nm | E21: @ 150 mm/sec
B22: Ball screw pitch | C22: 2 | D22: mm
B23: Ball screw dia | C23: 6 | D23: mm
A25: Parallel Kit Details | B25: Selected Parallel Kit Model | C25: Festo - EAMM-U-60-D40-55A-91 / 1210438
B26: Gear Ratio | C26: 1 | D26: ratio
B27: No Load Driving Torque | C27: 0.07 | D27: Nm
B28: Mass Momment of Inertia | C28: 26.7 | D28: Kgmm2
B29: Max. Transfereable torque | C29: 3 | D29: Nm
B30: Max. Rotational Speed | C30: 6000 | D30: rpm
A32: Guide Details | B32: Selected Guide Model | C32: Festo - EAGF-V2-KF-40-100 / 2782939
B33: Displacement Force required | C33: 15 | D33: N
B34: Moving Mass | C34: =(1283+(32*10))/1000 -> 1.603 | D34: Kg
B35: Max Withstand Force | C35: 1000 | D35: N
B36: Service Life for 100% loading | C36: 5000 | D36: Km
B38: Torque Required at ball screw shaft | C38: =C184 -> 0.26855385 | D38: Nm
B39: Speed Required at ball screw shaft | C39: =C118 -> 666.66667 | D39: rpm
B40: Linear Speed of the ball screw shaft | C40: =(C39/60)*C22 -> 22.222222 | D40: mm/sec
A42: Gear Box Details | B42: Selected Gear ratio | C42: 1 | D42: ratio
B43: Selected Gear Box Model | C43: Not required here
B44: Gearbox - Inertia | C44: 0 | D44: Kg-m2
B45: GB- Efficiency | C45: 0.97
B46: GB- No load running torque | C46: 0.01 | D46: Nm
...

Sheet Checklist
C2: selected | D2: Required
B3: Parameters | C3: Capacity | D3: Actual | E3: Utilization | F3: Result | G3: Remarks
A4: Motor Parameters | B4: Motor Rated Speed, rpm | C4: =IF(calc!C218<0.1,"",calc!C218) -> 3000 | D4: =calc!C219 -> 666.66667 | E4: =calc!C220 -> 0.22222222 | F4: =calc!C221 -> OK
B5: Motor Rated Torque, Nm | C5: =IF(calc!C224<0.01,"",calc!C224) -> 0.16 | D5: =calc!C225 -> 0.28685964 | E5: =calc!C226 -> 1.7928728 | F5: =calc!C227 -> Check Duty cycle
B6: Motor Duty cycle for Peak torque operation, % | C6: 0.2 | D6: =calc!C242 -> 0.76005424 | E6: =D6/C6 -> 3.8002712 | F6: =calc!C245 -> Peak Torque NOK
B7: Motor Mechanical Braking - power off, Nm | C7: =IF(calc!C263<0.01,"",calc!C263) | D7: =calc!C262 -> 0.0053872675 | E7: =calc!C264 -> #DIV/0! | F7: =calc!C265 -> #DIV/0!
B8: Motor Servo Lock Braking - regular operation, Nm | C8: =calc!C269 -> 0.16 | D8: =calc!C268 -> 0.0053872675 | E8: =calc!C270 -> 0.033670422 | F8: =calc!C271 -> OK
B9: Motor Inertia Ratio | C9: =calc!C253 -> 7 | D9: =calc!C252 -> 1.1395101 | E9: =calc!C254 -> 0.16278716 | F9: =calc!C255 -> OK
B10: Motor service life, yrs | C10: =calc!C283 -> 12.327416 | D10: =calc!C284 -> 10 | E10: =calc!C285 -> 0.8112 | F10: =calc!C286 -> Check | G10: Bearing life of motor is limited
B11: Motor Brake service Life, yrs | C11: =IF(calc!C292<0.01,"",calc!C292<0.01) | D11: =calc!C293 -> 10 | E11: =calc!C294 -> #DIV/0! | F11: =calc!C295 -> #DIV/0!
A12: Gearbox | B12: GearBox Input speed, rpm | C12: =IF(calc!C298<0.01,"",calc!C298) | D12: =calc!C299 -> 666.66667 | E12: =calc!C300 -> #DIV/0! | F12: =calc!C301 -> #DIV/0!
B13: GearBox Output Torque, Nm | C13: =IF(calc!C304<0.01,"",calc!C304) | D13: =calc!C305 -> 0.26855385 | E13: =calc!C306 -> #DIV/0! | F13: =calc!C307 -> #DIV/0!
B14: GearBox service life, yrs | C14: =IF(calc!C312<0.01,"",calc!C312) | D14: =calc!C313 -> 10 | E14: =calc!C314 -> #DIV/0! | F14: =calc!C315 -> #DIV/0!
A15: Ball screw | B15: Ball screw max speed, rpm | C15: =calc!C321 -> 12000 | D15: =calc!C322 -> 666.66667 | E15: =calc!C323 -> 0.055555556 | F15: =calc!C324 -> OK | G15: Wish list
B16: Ball screw max acceleration, mm/sec2 | C16: =calc!C328 -> 5000 | D16: =calc!C329 -> 98.765432 | E16: =calc!C330 -> 0.019753086 | F16: =calc!C331 -> OK | G16: Wish list
B17: Ball screw max torque | C17: =calc!C334 -> 3 | D17: =calc!C335 -> 0.26855385 | E17: =calc!C336 -> 0.089517951 | F17: =calc!C337 -> OK | G17: Wish list
B18: Axial Load on Ball screw, N | C18: =calc!C342 -> 3000 | D18: =calc!C341 -> 16.9246 | E18: =calc!C343 -> 0.0056415333 | F18: =calc!C344 -> OK | G18: Wish list
B19: Service life of the Ball screw, Yrs | C19: =calc!C359 -> 296.77113 | D19: =calc!C360 -> 10 | E19: =calc!C361 -> 0.033696 | F19: =calc!C362 -> OK | G19: Wish list
B20: Movement accuracy of the system, (+/-) micron | C20: =calc!C208 -> 10.325028 | D20: =calc!C209 -> 10 | E20: =calc!C210 -> 1.0325028 | F20: =calc!C211 -> NOK
B21: Overall System service life, yrs | C21: =MIN(C19,C14,C11,C10) -> 12.327416 | D21: =MAX(D19,D14,D11,D10) -> 10 | E21: =D21/C21 -> 0.8112 | F21: =IF(E21<0.8,"OK",IF(E21<0.9,"Check","NOK")) -> Check

Sheet Readings
A3: Output side
A4: RPM | B4: 900
A5: Torque | B5: 1.8 | C5: Nm
A6: Time | B6: 7 | C6: sec
A8: Input side
A9: RPM
A10: Torque | C10: Nm
A11: Time | C11: sec

Sheet User input
B2: Stn no | C2: Appl | D2: Total cycle time of machine | E2: Total operating time per cycle | F2: Expected service life of Machine | G2: Movement Stroke required | H2: Cycle time available for single movement | I2: External Force on the moving mass | J2: Moving mass | K2: Tilt angle of the setup | L2: Acceleration % | M2: Safety factor % | N2: Movement accuracy required (+/-) | P2: selected servo motor
B3: OP10 | C3: App-1
B4: OP10 | C4: App-2
B5: OP20 | C5: App-1

Sheet Revisions
A3: Updates required
A4: 1 | B4: Servo lock - overload calculation with duty cycle pending
A5: 2 | B5: Peak torque check for GB
A6: 3 | B6: Gearbox - duty cycle check include
